Workbook

Sheet Exec Summary
A1: Anthropic, PBC (Claude) | $ANT | Valuation Executive Summary
A2: ="Prepared: "&TEXT(TODAY(),"d-mmm-yyyy")&" | Source: Form S-1 filed 26-Oct-2026 | 15-year DCF, Bear / Base / Bull, probability-weighted | $ in Millions except per share" -> Prepared: 28-Oct-2026 | Source: Form S-1 filed 26-Oct-2026 | 15-year DCF, Bear / Base / Bull, probability-weighted | $ in Millions except per share
A4: INVESTMENT THESIS
A5: ="Anthropic is filing to IPO after revenue went from $4.6B in FY2025 to $"&TEXT(Historicals!F7/1000,"0.0")&"B in 1H26 alone. The Q2'26 run-rate is $"&TEXT(Historicals!G33*4/1000,"0")&"B, and Q2 was the first quarter with a GAAP operating profit ($"&TEXT(Historicals!G41,"#,##0")&"M)." -> Anthropic is filing to IPO after revenue went from $4.6B in FY2025 to $16.3B in 1H26 alone. The Q2'26 run-rate is $46B, and Q2 was the first quarter with a GAAP operating profit ($974M).
A6: =" (1) Demand: over "&TEXT(Historicals!H168,"#,##0")&" customers spend ≥$100K a year (up from ~950 a year earlier) and Net Revenue Retention is ~"&TEXT(Historicals!H171,"0%")&". Consumption (API / pay-for-intelligence) is "&TEXT(Historicals!F72/Historicals!F7,"0%")&" of 1H26 revenue." -> (1) Demand: over 11,900 customers spend ≥$100K a year (up from ~950 a year earlier) and Net Revenue Retention is ~900%. Consumption (API / pay-for-intelligence) is 80% of 1H26 revenue.
A7: =" (2) Compute: compute & infrastructure costs fell from 251% of revenue (Q1'25) to "&TEXT(Historicals!G35/Historicals!G33,"0%")&" (Q2'26). We model inference and training compute separately, the GW of capacity in service, and the move to owned capacity (Anthropic Direct)." -> (2) Compute: compute & infrastructure costs fell from 251% of revenue (Q1'25) to 48% (Q2'26). We model inference and training compute separately, the GW of capacity in service, and the move to owned capacity (Anthropic Direct).
A8: =" (3) Cash: about $"&TEXT((WACC!B56+WACC!B57)/1000,"#,##0.0")&"B of cash + short-term investments at "&Actuals!B7&" (pre-IPO); "&TEXT(WACC!B40,"0%")&" of the convertible notes are assumed to convert at the IPO. Compute commitments are large, and many are prepaid 12-18 months ahead." -> (3) Cash: about $131.7B of cash + short-term investments at Jun 2026A (pre-IPO); 100% of the convertible notes are assumed to convert at the IPO. Compute commitments are large, and many are prepaid 12-18 months ahead.
A9: =" View: the probability-weighted value of $"&TEXT(Dashboard!D12,"#,##0")&"/share compares with an entry price of $"&TEXT(Dashboard!B5,"#,##0")&". Base case "&TEXT(Dashboard!D10,"$#,##0")&"; Base IRR to FY2031E "&TEXT(Dashboard!G10,"0.0%")&" vs a "&TEXT(Dashboard!B16,"0%")&" hurdle → "&Dashboard!B21&"." -> View: the probability-weighted value of $139/share compares with an entry price of $59. Base case $112; Base IRR to FY2031E 23.3% vs a 13% hurdle → BUY – start / add to position.
A11: VALUATION CONCLUSION (implied value per share, fully diluted post-IPO)
A12: Measure | B12: Bear | C12: Base | D12: Bull | E12: Prob-weighted | G12: Notes
A13: Value per share – blended (50% GG / 50% exit) | B13: =Dashboard!D9 -> 30.494614 | C13: =Dashboard!D10 -> 111.87893 | D13: =Dashboard!D11 -> 301.27484 | E13: =Dashboard!D12 -> 138.88183 | G13: Blend weight: DCF engines, cell B153
A14: Value per share – Gordon Growth | B14: =Dashboard!B9 -> 29.192587 | C14: =Dashboard!B10 -> 102.40074 | D14: =Dashboard!B11 -> 263.7759 | E14: =Dashboard!B12 -> 124.44249 | G14: Terminal value capitalised at the terminal-period WACC
A15: Value per share – Exit multiple | B15: =Dashboard!C9 -> 31.79664 | C15: =Dashboard!C10 -> 121.35712 | D15: =Dashboard!C11 -> 338.77377 | E15: =Dashboard!C12 -> 153.32116 | G15: Exit EV/EBITDA applied to FY2040E EBITDA
A16: Upside / (downside) to entry price | B16: =Dashboard!E9 -> -0.48226462 | C16: =Dashboard!E10 -> 0.89947251 | D16: =Dashboard!E11 -> 4.1150227 | E16: =Dashboard!E12 -> 1.3579258
A17: Expected IRR to FY2031E | B17: =Dashboard!G9 -> -0.04679228 | C17: =Dashboard!G10 -> 0.23308319 | D17: =Dashboard!G11 -> 0.48464665 | E17: =Dashboard!G12 -> 0.28133475 | G17: Exit at FY2031E EBITDA × scenario exit multiple
A18: Enterprise value – blended ($M) | B18: ='DCF Bear'!D160 -> 307080.55 | C18: ='DCF Base'!D160 -> 1530280.2 | D18: ='DCF Bull'!D160 -> 4376885.1 | E18: =B18*Dashboard!F9+C18*Dashboard!F10+D18*Dashboard!F11 -> 1936131.5
A19: Entry / IPO price | B19: =Dashboard!B5 -> 58.9
A20: Recommendation | B20: =Dashboard!B21 -> BUY – start / add to position
A22: KEY ASSUMPTIONS (Base case – edit on Drivers / WACC)
A23: Item | B23: Value | G23: Source
A24: FY2026E revenue ($M) | B24: ='DCF Base'!E65 -> 54504.162 | G24: 1H26A + Q3/Q4 QoQ build
A25: FY2027E revenue growth | B25: ='DCF Base'!F66 -> 1.08 | G25: Drivers
A26: FY2030E revenue ($M) | B26: ='DCF Base'!I65 -> 326334.3 | G26: Consumption + subscription build
A27: FY2040E revenue ($M) | B27: ='DCF Base'!S65 -> 902029.72
A28: FY2040E compute need % of revenue | B28: ='DCF Base'!S79 -> 0.31 | G28: Inference + training
A29: FY2040E compute capacity (GW) | B29: ='DCF Base'!S80 -> 30.91978 | G29: Rental-equivalent cost per GW-yr
A30: FY2040E EBIT margin | B30: ='DCF Base'!S120 -> 0.45170842 | G30: SBC treated as a cost
A31: WACC (explicit period) | B31: =WACC!B23 -> 0.13367493 | G31: ="CAPM; βu "&TEXT(WACC!B15,"0.00")&" (peer median), Rf "&TEXT(WACC!B7,"0.0%")&", ERP "&TEXT(WACC!B8,"0.0%")&", +"&TEXT(WACC!B10,"0.0%")&" specific" -> CAPM; βu 1.38 (peer median), Rf 5.0%, ERP 5.0%, +1.5% specific
A32: Terminal-period WACC | B32: =WACC!B70 -> 0.10015294 | G32: Mature βu 1.00
A33: Terminal growth / exit EV/EBITDA | B33: =TEXT(WACC!C28,"0.0%")&" / "&TEXT(WACC!D28,"0.0x") -> 3.5% / 14.0x | G33: Drivers
A34: Fully diluted shares post-IPO (M) | B34: =WACC!B52 -> 15663.257 | G34: Split-adjusted (10-for-1, Sep-2026): common + preferred×10 + notes + options (TSM) + RSUs + IPO shares
A36: S-1 ACTUALS SNAPSHOT
A37: Metric | B37: Value | G37: Period / source
A38: Revenue ($M) | B38: =Historicals!D7 -> 4585 | G38: FY2025A
A39: Revenue ($M) | B39: =Historicals!F7 -> 16286 | G39: 6M 2026A (vs $1,163M 6M 2025A)
A40: Quarterly revenue run-rate ($M) | B40: =Historicals!G33*4 -> 46220 | G40: Q2 2026A × 4
A41: Adjusted operating income ($M) | B41: =Historicals!F27 -> 1618 | G41: 6M 2026A
A42: Operating cash flow ($M) | B42: =Historicals!F128 -> 3929 | G42: 6M 2026A
A43: Cash + short-term investments ($M) | B43: =Historicals!D82+Historicals!D83 -> 131651 | G43: 46203
A44: Customers ≥$100K TTM revenue | B44: =Historicals!H168 -> 11900 | G44: 46295
...

Sheet Dashboard
A1: Anthropic, PBC (Claude) | $ANT | DCF Valuation Dashboard (Bear / Base / Bull)
A2: Single-segment DCF, 3 scenario engines, probability-weighted | Form S-1 filed 26-Oct-2026 | $ in Millions except per share
A4: ① ENTER PRICE TO SEE UPSIDE / DOWNSIDE
A5: Entry / IPO price ($ per share) | B5: =ROUND(Historicals!B178/WACC!B37,2) -> 58.9 | C5: ← Placeholder = Series H-1 $589.01 ÷ 10 (split-adjusted $/common). Overwrite with IPO price once set
A7: ② IMPLIED VALUE PER SHARE BY SCENARIO (fully diluted, post-IPO)
A8: Scenario | B8: Gordon Growth | C8: Exit Multiple | D8: Blended | E8: Upside / (Down) | F8: Probability | G8: IRR to FY2031E (from purchase date) | H8: MOIC
A9: Bear | B9: ='DCF Bear'!B165 -> 29.192587 | C9: ='DCF Bear'!C165 -> 31.79664 | D9: ='DCF Bear'!D165 -> 30.494614 | E9: =D9/$B$5-1 -> -0.48226462 | F9: =WACC!E27 -> 0.25 | G9: ='DCF Bear'!B184 -> -0.04679228 | H9: ='DCF Bear'!B185 -> 0.78014334
A10: Base | B10: ='DCF Base'!B165 -> 102.40074 | C10: ='DCF Base'!C165 -> 121.35712 | D10: ='DCF Base'!D165 -> 111.87893 | E10: =D10/$B$5-1 -> 0.89947251 | F10: =WACC!E28 -> 0.5 | G10: ='DCF Base'!B184 -> 0.23308319 | H10: ='DCF Base'!B185 -> 2.9608424
A11: Bull | B11: ='DCF Bull'!B165 -> 263.7759 | C11: ='DCF Bull'!C165 -> 338.77377 | D11: ='DCF Bull'!D165 -> 301.27484 | E11: =D11/$B$5-1 -> 4.1150227 | F11: =WACC!E29 -> 0.25 | G11: ='DCF Bull'!B184 -> 0.48464665 | H11: ='DCF Bull'!B185 -> 7.7472707
A12: Probability-weighted | B12: =SUMPRODUCT(B9:B11,$F$9:$F$11) -> 124.44249 | C12: =SUMPRODUCT(C9:C11,$F$9:$F$11) -> 153.32116 | D12: =SUMPRODUCT(D9:D11,$F$9:$F$11) -> 138.88183 | E12: =D12/$B$5-1 -> 1.3579258 | F12: =SUM(F9:F11) -> 1 | G12: =((F9*'DCF Bear'!B182+F10*'DCF Base'!B182+F11*'DCF Bull'!B182)/$B$5)^(1/'DCF Base'!B183)-1 -> 0.28133475 | H12: =SUMPRODUCT(H9:H11,$F$9:$F$11) -> 3.6122747
A14: ③ INVESTMENT DECISION (personal underwriting rules)
A15: Item | B15: Value | H15: Note
A16: Hurdle rate (required annual return) | B16: =WACC!B18 -> 0.13496243 | H16: Linked to CAPM cost of equity (WACC!B18) – only override upward
A17: Required margin of safety vs probability-weighted value | B17: 0.2 | H17: Frontier-AI model risk; compute commitments
A18: Probability-weighted value per share | B18: =D12 -> 138.88183
A19: Maximum entry price (value × (1 − margin of safety)) | B19: =B18*(1-B17) -> 111.10546 | H19: Price discipline anchor
A20: Base-case IRR minus hurdle | B20: =G10-B16 -> 0.098120755
A21: Recommendation | B21: =IF(AND($B$5<=B19,G10>=B16),"BUY – start / add to position",IF($B$5<=B18,"HOLD – watchlist, thin margin of safety","PASS at this price")) -> BUY – start / add to position | H21: Driven by entered price vs value & IRR
A22: Market-implied perpetual growth (Base engine reverse DCF) | B22: ='DCF Base'!B178 -> -0.24921136 | H22: vs Base terminal growth assumption
A23: Market-implied FY2040E exit EV / EBITDA (Base) | B23: ='DCF Base'!B179 -> 1.3755728 | H23: vs Base exit multiple
A24: Market-implied EV / FY2027E revenue | B24: =Comps!K43 -> 6.4745512 | H24: Cross-check vs comps medians
A26: ④ BASE CASE – ENTERPRISE VALUE TO EQUITY BRIDGE
A27: ($M) | B27: Gordon Growth | C27: Exit Multiple | D27: Blended
A28: Sum of PV of UFCF | B28: ='DCF Base'!B155 -> 631726.52 | C28: ='DCF Base'!C155 -> 631726.52 | D28: ='DCF Base'!D155 -> 631726.52
A29: PV of terminal value | B29: ='DCF Base'!B159 -> 756097.19 | C29: ='DCF Base'!C159 -> 1041010.1 | D29: ='DCF Base'!D159 -> 898553.65
A30: Enterprise value | B30: ='DCF Base'!B160 -> 1387823.7 | C30: ='DCF Base'!C160 -> 1672736.6 | D30: ='DCF Base'!D160 -> 1530280.2
A31: TV % of EV | B31: ='DCF Base'!B161 -> 0.54480781 | C31: ='DCF Base'!C161 -> 0.62233952 | D31: ='DCF Base'!D161 -> 0.58718244
A32: (+) Net cash incl. IPO proceeds | B32: ='DCF Base'!B162 -> 151251 | C32: ='DCF Base'!C162 -> 151251 | D32: ='DCF Base'!D162 -> 151251
A33: Equity value | B33: ='DCF Base'!B163 -> 1603929.1 | C33: ='DCF Base'!C163 -> 1900847.9 | D33: ='DCF Base'!D163 -> 1752388.5
A34: Fully diluted shares (M) | B34: ='DCF Base'!B164 -> 15663.257 | C34: ='DCF Base'!C164 -> 15663.257 | D34: ='DCF Base'!D164 -> 15663.257
A35: Implied value per share | B35: ='DCF Base'!B165 -> 102.40074 | C35: ='DCF Base'!C165 -> 121.35712 | D35: ='DCF Base'!D165 -> 111.87893
A37: ⑤ SENSITIVITY (Base) – value per share, Gordon Growth: WACC vs terminal growth
A38: ='DCF Base'!A188 -> WACC ↓ \ Tg → | B38: ='DCF Base'!B188 -> 0.025 | C38: ='DCF Base'!C188 -> 0.03 | D38: ='DCF Base'!D188 -> 0.035 | E38: ='DCF Base'!E188 -> 0.04 | F38: ='DCF Base'!F188 -> 0.045
A39: ='DCF Base'!A189 -> 0.11367493 | B39: ='DCF Base'!B189 -> 135.85865 | C39: ='DCF Base'!C189 -> 143.86295 | D39: ='DCF Base'!D189 -> 153.63995 | E39: ='DCF Base'!E189 -> 165.85189 | F39: ='DCF Base'!F189 -> 181.53778
A40: ='DCF Base'!A190 -> 0.12367493 | B40: ='DCF Base'!B190 -> 112.34621 | C40: ='DCF Base'!C190 -> 117.35452 | D40: ='DCF Base'!D190 -> 123.2709 | E40: ='DCF Base'!E190 -> 130.36695 | F40: ='DCF Base'!F190 -> 139.03456
A41: ='DCF Base'!A191 -> 0.13367493 | B41: ='DCF Base'!B191 -> 95.285528 | C41: ='DCF Base'!C191 -> 98.589573 | D41: ='DCF Base'!D191 -> 102.40074 | E41: ='DCF Base'!E191 -> 106.84548 | F41: ='DCF Base'!F191 -> 112.09612
A42: ='DCF Base'!A192 -> 0.14367493 | B42: ='DCF Base'!B192 -> 82.390462 | C42: ='DCF Base'!C192 -> 84.657866 | D42: ='DCF Base'!D192 -> 87.226975 | E42: ='DCF Base'!E192 -> 90.1623 | F42: ='DCF Base'!F192 -> 93.548153
A43: ='DCF Base'!A193 -> 0.15367493 | B43: ='DCF Base'!B193 -> 72.337188 | C43: ='DCF Base'!C193 -> 73.94155 | D43: ='DCF Base'!D193 -> 75.734322 | E43: ='DCF Base'!E193 -> 77.750762 | F43: ='DCF Base'!F193 -> 80.035515
A45: ⑥ SENSITIVITY (Base) – value per share, Exit Multiple: WACC vs exit EV/EBITDA
A46: ='DCF Base'!A196 -> WACC ↓ \ Exit multiple → | B46: ='DCF Base'!B196 -> 10 | C46: ='DCF Base'!C196 -> 12 | D46: ='DCF Base'!D196 -> 14 | E46: ='DCF Base'!E196 -> 16 | F46: ='DCF Base'!F196 -> 18
...

Sheet Graphs
A1: Anthropic ($ANT) – Charts
A2: Source: Historicals (Form S-1 filed 26-Oct-2026), DCF Bear / Base / Bull engines, Dashboard | $ in Millions unless stated | chart data block in columns U:AK (linked, do not overwrite)
U4: Chart 1 title (linked to chart):
U5: ="Income statement bridge – "&Actuals!B5&" ($M), as reported in S-1 / 10-Q" -> Income statement bridge – 6M 2026A ($M), as reported in S-1 / 10-Q
U6: CHART DATA 1: YTD INCOME STATEMENT BRIDGE (Historicals rows 7–22, 72–73; period = Actuals!B5)
U7: Type | V7: Value | W7: Start | X7: End | Y7: Low | Z7: High | AA7: Category | AB7: Inv + | AC7: Inv − | AD7: Consumption | AE7: Subscription | AF7: Costs | AG7: Costs | AH7: Income | AI7: Income | AJ7: Subtotal | AK7: Subtotal
U8: Rev | V8: =INDEX(Historicals!$B$7:$K$7,MATCH(Actuals!$B$5,Historicals!$B$6:$K$6,0)) -> 16286 | W8: =0 -> 0 | X8: =IF(U8="Total",V8,W8+V8) -> 16286 | Y8: =MIN(W8,X8) -> 0 | Z8: =MAX(W8,X8) -> 16286 | AA8: ="Revenue"&CHAR(10)&TEXT(V8,"$#,##0;($#,##0);-") -> Revenue $16,286 | AB8: =IF(U8="Rev",0,IF(Y8>0,Y8,0)) -> 0 | AC8: =IF(Z8<0,Z8,0) -> 0 | AD8: =IF(U8="Rev",INDEX(Historicals!$B$72:$K$72,MATCH(Actuals!$B$5,Historicals!$B$68:$K$68,0)),0) -> 13064 | AE8: =IF(U8="Rev",INDEX(Historicals!$B$73:$K$73,MATCH(Actuals!$B$5,Historicals!$B$68:$K$68,0)),0) -> 3222 | AF8: =IF(AND(U8="Step",V8<0),MAX(Z8,0)-MAX(Y8,0),0) -> 0 | AG8: =IF(AND(U8="Step",V8<0),MIN(Y8,0)-MIN(Z8,0),0) -> 0 | AH8: =IF(AND(U8="Step",V8>0),MAX(Z8,0)-MAX(Y8,0),0) -> 0 | AI8: =IF(AND(U8="Step",V8>0),MIN(Y8,0)-MIN(Z8,0),0) -> 0 | AJ8: =IF(U8="Total",MAX(Z8,0)-MAX(Y8,0),0) -> 0 | AK8: =IF(U8="Total",MIN(Y8,0)-MIN(Z8,0),0) -> 0
U9: Step | V9: =-INDEX(Historicals!$B$9:$K$9,MATCH(Actuals!$B$5,Historicals!$B$6:$K$6,0)) -> -8945 | W9: =IF(U9="Total",0,X8) -> 16286 | X9: =IF(U9="Total",V9,W9+V9) -> 7341 | Y9: =MIN(W9,X9) -> 7341 | Z9: =MAX(W9,X9) -> 16286 | AA9: ="Compute & infra"&CHAR(10)&TEXT(V9,"$#,##0;($#,##0);-") -> Compute & infra ($8,945) | AB9: =IF(U9="Rev",0,IF(Y9>0,Y9,0)) -> 7341 | AC9: =IF(Z9<0,Z9,0) -> 0 | AD9: =IF(U9="Rev",INDEX(Historicals!$B$72:$K$72,MATCH(Actuals!$B$5,Historicals!$B$68:$K$68,0)),0) -> 0 | AE9: =IF(U9="Rev",INDEX(Historicals!$B$73:$K$73,MATCH(Actuals!$B$5,Historicals!$B$68:$K$68,0)),0) -> 0 | AF9: =IF(AND(U9="Step",V9<0),MAX(Z9,0)-MAX(Y9,0),0) -> 8945 | AG9: =IF(AND(U9="Step",V9<0),MIN(Y9,0)-MIN(Z9,0),0) -> 0 | AH9: =IF(AND(U9="Step",V9>0),MAX(Z9,0)-MAX(Y9,0),0) -> 0 | AI9: =IF(AND(U9="Step",V9>0),MIN(Y9,0)-MIN(Z9,0),0) -> 0 | AJ9: =IF(U9="Total",MAX(Z9,0)-MAX(Y9,0),0) -> 0 | AK9: =IF(U9="Total",MIN(Y9,0)-MIN(Z9,0),0) -> 0
U10: Step | V10: =-INDEX(Historicals!$B$10:$K$10,MATCH(Actuals!$B$5,Historicals!$B$6:$K$6,0)) -> -3152 | W10: =IF(U10="Total",0,X9) -> 7341 | X10: =IF(U10="Total",V10,W10+V10) -> 4189 | Y10: =MIN(W10,X10) -> 4189 | Z10: =MAX(W10,X10) -> 7341 | AA10: ="Personnel"&CHAR(10)&TEXT(V10,"$#,##0;($#,##0);-") -> Personnel ($3,152) | AB10: =IF(U10="Rev",0,IF(Y10>0,Y10,0)) -> 4189 | AC10: =IF(Z10<0,Z10,0) -> 0 | AD10: =IF(U10="Rev",INDEX(Historicals!$B$72:$K$72,MATCH(Actuals!$B$5,Historicals!$B$68:$K$68,0)),0) -> 0 | AE10: =IF(U10="Rev",INDEX(Historicals!$B$73:$K$73,MATCH(Actuals!$B$5,Historicals!$B$68:$K$68,0)),0) -> 0 | AF10: =IF(AND(U10="Step",V10<0),MAX(Z10,0)-MAX(Y10,0),0) -> 3152 | AG10: =IF(AND(U10="Step",V10<0),MIN(Y10,0)-MIN(Z10,0),0) -> 0 | AH10: =IF(AND(U10="Step",V10>0),MAX(Z10,0)-MAX(Y10,0),0) -> 0 | AI10: =IF(AND(U10="Step",V10>0),MIN(Y10,0)-MIN(Z10,0),0) -> 0 | AJ10: =IF(U10="Total",MAX(Z10,0)-MAX(Y10,0),0) -> 0 | AK10: =IF(U10="Total",MIN(Y10,0)-MIN(Z10,0),0) -> 0
U11: Step | V11: =-INDEX(Historicals!$B$11:$K$11,MATCH(Actuals!$B$5,Historicals!$B$6:$K$6,0)) -> 0 | W11: =IF(U11="Total",0,X10) -> 4189 | X11: =IF(U11="Total",V11,W11+V11) -> 4189 | Y11: =MIN(W11,X11) -> 4189 | Z11: =MAX(W11,X11) -> 4189 | AA11: ="Bartz settlement"&CHAR(10)&TEXT(V11,"$#,##0;($#,##0);-") -> Bartz settlement - | AB11: =IF(U11="Rev",0,IF(Y11>0,Y11,0)) -> 4189 | AC11: =IF(Z11<0,Z11,0) -> 0 | AD11: =IF(U11="Rev",INDEX(Historicals!$B$72:$K$72,MATCH(Actuals!$B$5,Historicals!$B$68:$K$68,0)),0) -> 0 | AE11: =IF(U11="Rev",INDEX(Historicals!$B$73:$K$73,MATCH(Actuals!$B$5,Historicals!$B$68:$K$68,0)),0) -> 0 | AF11: =IF(AND(U11="Step",V11<0),MAX(Z11,0)-MAX(Y11,0),0) -> 0 | AG11: =IF(AND(U11="Step",V11<0),MIN(Y11,0)-MIN(Z11,0),0) -> 0 | AH11: =IF(AND(U11="Step",V11>0),MAX(Z11,0)-MAX(Y11,0),0) -> 0 | AI11: =IF(AND(U11="Step",V11>0),MIN(Y11,0)-MIN(Z11,0),0) -> 0 | AJ11: =IF(U11="Total",MAX(Z11,0)-MAX(Y11,0),0) -> 0 | AK11: =IF(U11="Total",MIN(Y11,0)-MIN(Z11,0),0) -> 0
U12: Step | V12: =-INDEX(Historicals!$B$12:$K$12,MATCH(Actuals!$B$5,Historicals!$B$6:$K$6,0)) -> -3168 | W12: =IF(U12="Total",0,X11) -> 4189 | X12: =IF(U12="Total",V12,W12+V12) -> 1021 | Y12: =MIN(W12,X12) -> 1021 | Z12: =MAX(W12,X12) -> 4189 | AA12: ="S&M & partnerships"&CHAR(10)&TEXT(V12,"$#,##0;($#,##0);-") -> S&M & partnerships ($3,168) | AB12: =IF(U12="Rev",0,IF(Y12>0,Y12,0)) -> 1021 | AC12: =IF(Z12<0,Z12,0) -> 0 | AD12: =IF(U12="Rev",INDEX(Historicals!$B$72:$K$72,MATCH(Actuals!$B$5,Historicals!$B$68:$K$68,0)),0) -> 0 | AE12: =IF(U12="Rev",INDEX(Historicals!$B$73:$K$73,MATCH(Actuals!$B$5,Historicals!$B$68:$K$68,0)),0) -> 0 | AF12: =IF(AND(U12="Step",V12<0),MAX(Z12,0)-MAX(Y12,0),0) -> 3168 | AG12: =IF(AND(U12="Step",V12<0),MIN(Y12,0)-MIN(Z12,0),0) -> 0 | AH12: =IF(AND(U12="Step",V12>0),MAX(Z12,0)-MAX(Y12,0),0) -> 0 | AI12: =IF(AND(U12="Step",V12>0),MIN(Y12,0)-MIN(Z12,0),0) -> 0 | AJ12: =IF(U12="Total",MAX(Z12,0)-MAX(Y12,0),0) -> 0 | AK12: =IF(U12="Total",MIN(Y12,0)-MIN(Z12,0),0) -> 0
U13: Step | V13: =-INDEX(Historicals!$B$13:$K$13,MATCH(Actuals!$B$5,Historicals!$B$6:$K$6,0)) -> -1714 | W13: =IF(U13="Total",0,X12) -> 1021 | X13: =IF(U13="Total",V13,W13+V13) -> -693 | Y13: =MIN(W13,X13) -> -693 | Z13: =MAX(W13,X13) -> 1021 | AA13: ="Other op. & admin"&CHAR(10)&TEXT(V13,"$#,##0;($#,##0);-") -> Other op. & admin ($1,714) | AB13: =IF(U13="Rev",0,IF(Y13>0,Y13,0)) -> 0 | AC13: =IF(Z13<0,Z13,0) -> 0 | AD13: =IF(U13="Rev",INDEX(Historicals!$B$72:$K$72,MATCH(Actuals!$B$5,Historicals!$B$68:$K$68,0)),0) -> 0 | AE13: =IF(U13="Rev",INDEX(Historicals!$B$73:$K$73,MATCH(Actuals!$B$5,Historicals!$B$68:$K$68,0)),0) -> 0 | AF13: =IF(AND(U13="Step",V13<0),MAX(Z13,0)-MAX(Y13,0),0) -> 1021 | AG13: =IF(AND(U13="Step",V13<0),MIN(Y13,0)-MIN(Z13,0),0) -> -693 | AH13: =IF(AND(U13="Step",V13>0),MAX(Z13,0)-MAX(Y13,0),0) -> 0 | AI13: =IF(AND(U13="Step",V13>0),MIN(Y13,0)-MIN(Z13,0),0) -> 0 | AJ13: =IF(U13="Total",MAX(Z13,0)-MAX(Y13,0),0) -> 0 | AK13: =IF(U13="Total",MIN(Y13,0)-MIN(Z13,0),0) -> 0
U14: Total | V14: =INDEX(Historicals!$B$15:$K$15,MATCH(Actuals!$B$5,Historicals!$B$6:$K$6,0)) -> -693 | W14: =IF(U14="Total",0,X13) -> 0 | X14: =IF(U14="Total",V14,W14+V14) -> -693 | Y14: =MIN(W14,X14) -> -693 | Z14: =MAX(W14,X14) -> 0 | AA14: ="Operating income"&CHAR(10)&TEXT(V14,"$#,##0;($#,##0);-") -> Operating income ($693) | AB14: =IF(U14="Rev",0,IF(Y14>0,Y14,0)) -> 0 | AC14: =IF(Z14<0,Z14,0) -> 0 | AD14: =IF(U14="Rev",INDEX(Historicals!$B$72:$K$72,MATCH(Actuals!$B$5,Historicals!$B$68:$K$68,0)),0) -> 0 | AE14: =IF(U14="Rev",INDEX(Historicals!$B$73:$K$73,MATCH(Actuals!$B$5,Historicals!$B$68:$K$68,0)),0) -> 0 | AF14: =IF(AND(U14="Step",V14<0),MAX(Z14,0)-MAX(Y14,0),0) -> 0 | AG14: =IF(AND(U14="Step",V14<0),MIN(Y14,0)-MIN(Z14,0),0) -> 0 | AH14: =IF(AND(U14="Step",V14>0),MAX(Z14,0)-MAX(Y14,0),0) -> 0 | AI14: =IF(AND(U14="Step",V14>0),MIN(Y14,0)-MIN(Z14,0),0) -> 0 | AJ14: =IF(U14="Total",MAX(Z14,0)-MAX(Y14,0),0) -> 0 | AK14: =IF(U14="Total",MIN(Y14,0)-MIN(Z14,0),0) -> -693
U15: Step | V15: =INDEX(Historicals!$B$16:$K$16,MATCH(Actuals!$B$5,Historicals!$B$6:$K$6,0)) -> 1111 | W15: =IF(U15="Total",0,X14) -> -693 | X15: =IF(U15="Total",V15,W15+V15) -> 418 | Y15: =MIN(W15,X15) -> -693 | Z15: =MAX(W15,X15) -> 418 | AA15: ="Interest income"&CHAR(10)&TEXT(V15,"$#,##0;($#,##0);-") -> Interest income $1,111 | AB15: =IF(U15="Rev",0,IF(Y15>0,Y15,0)) -> 0 | AC15: =IF(Z15<0,Z15,0) -> 0 | AD15: =IF(U15="Rev",INDEX(Historicals!$B$72:$K$72,MATCH(Actuals!$B$5,Historicals!$B$68:$K$68,0)),0) -> 0 | AE15: =IF(U15="Rev",INDEX(Historicals!$B$73:$K$73,MATCH(Actuals!$B$5,Historicals!$B$68:$K$68,0)),0) -> 0 | AF15: =IF(AND(U15="Step",V15<0),MAX(Z15,0)-MAX(Y15,0),0) -> 0 | AG15: =IF(AND(U15="Step",V15<0),MIN(Y15,0)-MIN(Z15,0),0) -> 0 | AH15: =IF(AND(U15="Step",V15>0),MAX(Z15,0)-MAX(Y15,0),0) -> 418 | AI15: =IF(AND(U15="Step",V15>0),MIN(Y15,0)-MIN(Z15,0),0) -> -693 | AJ15: =IF(U15="Total",MAX(Z15,0)-MAX(Y15,0),0) -> 0 | AK15: =IF(U15="Total",MIN(Y15,0)-MIN(Z15,0),0) -> 0
U16: Step | V16: =INDEX(Historicals!$B$17:$K$17,MATCH(Actuals!$B$5,Historicals!$B$6:$K$6,0)) -> -72388 | W16: =IF(U16="Total",0,X15) -> 418 | X16: =IF(U16="Total",V16,W16+V16) -> -71970 | Y16: =MIN(W16,X16) -> -71970 | Z16: =MAX(W16,X16) -> 418 | AA16: ="FV change – notes & SAFEs"&CHAR(10)&TEXT(V16,"$#,##0;($#,##0);-") -> FV change – notes & SAFEs ($72,388) | AB16: =IF(U16="Rev",0,IF(Y16>0,Y16,0)) -> 0 | AC16: =IF(Z16<0,Z16,0) -> 0 | AD16: =IF(U16="Rev",INDEX(Historicals!$B$72:$K$72,MATCH(Actuals!$B$5,Historicals!$B$68:$K$68,0)),0) -> 0 | AE16: =IF(U16="Rev",INDEX(Historicals!$B$73:$K$73,MATCH(Actuals!$B$5,Historicals!$B$68:$K$68,0)),0) -> 0 | AF16: =IF(AND(U16="Step",V16<0),MAX(Z16,0)-MAX(Y16,0),0) -> 418 | AG16: =IF(AND(U16="Step",V16<0),MIN(Y16,0)-MIN(Z16,0),0) -> -71970 | AH16: =IF(AND(U16="Step",V16>0),MAX(Z16,0)-MAX(Y16,0),0) -> 0 | AI16: =IF(AND(U16="Step",V16>0),MIN(Y16,0)-MIN(Z16,0),0) -> 0 | AJ16: =IF(U16="Total",MAX(Z16,0)-MAX(Y16,0),0) -> 0 | AK16: =IF(U16="Total",MIN(Y16,0)-MIN(Z16,0),0) -> 0
U17: Step | V17: =INDEX(Historicals!$B$18:$K$18,MATCH(Actuals!$B$5,Historicals!$B$6:$K$6,0)) -> -8757 | W17: =IF(U17="Total",0,X16) -> -71970 | X17: =IF(U17="Total",V17,W17+V17) -> -80727 | Y17: =MIN(W17,X17) -> -80727 | Z17: =MAX(W17,X17) -> -71970 | AA17: ="Other income (exp.)"&CHAR(10)&TEXT(V17,"$#,##0;($#,##0);-") -> Other income (exp.) ($8,757) | AB17: =IF(U17="Rev",0,IF(Y17>0,Y17,0)) -> 0 | AC17: =IF(Z17<0,Z17,0) -> -71970 | AD17: =IF(U17="Rev",INDEX(Historicals!$B$72:$K$72,MATCH(Actuals!$B$5,Historicals!$B$68:$K$68,0)),0) -> 0 | AE17: =IF(U17="Rev",INDEX(Historicals!$B$73:$K$73,MATCH(Actuals!$B$5,Historicals!$B$68:$K$68,0)),0) -> 0 | AF17: =IF(AND(U17="Step",V17<0),MAX(Z17,0)-MAX(Y17,0),0) -> 0 | AG17: =IF(AND(U17="Step",V17<0),MIN(Y17,0)-MIN(Z17,0),0) -> -8757 | AH17: =IF(AND(U17="Step",V17>0),MAX(Z17,0)-MAX(Y17,0),0) -> 0 | AI17: =IF(AND(U17="Step",V17>0),MIN(Y17,0)-MIN(Z17,0),0) -> 0 | AJ17: =IF(U17="Total",MAX(Z17,0)-MAX(Y17,0),0) -> 0 | AK17: =IF(U17="Total",MIN(Y17,0)-MIN(Z17,0),0) -> 0
U18: Total | V18: =INDEX(Historicals!$B$20:$K$20,MATCH(Actuals!$B$5,Historicals!$B$6:$K$6,0)) -> -80727 | W18: =IF(U18="Total",0,X17) -> 0 | X18: =IF(U18="Total",V18,W18+V18) -> -80727 | Y18: =MIN(W18,X18) -> -80727 | Z18: =MAX(W18,X18) -> 0 | AA18: ="Pre-tax loss"&CHAR(10)&TEXT(V18,"$#,##0;($#,##0);-") -> Pre-tax loss ($80,727) | AB18: =IF(U18="Rev",0,IF(Y18>0,Y18,0)) -> 0 | AC18: =IF(Z18<0,Z18,0) -> 0 | AD18: =IF(U18="Rev",INDEX(Historicals!$B$72:$K$72,MATCH(Actuals!$B$5,Historicals!$B$68:$K$68,0)),0) -> 0 | AE18: =IF(U18="Rev",INDEX(Historicals!$B$73:$K$73,MATCH(Actuals!$B$5,Historicals!$B$68:$K$68,0)),0) -> 0 | AF18: =IF(AND(U18="Step",V18<0),MAX(Z18,0)-MAX(Y18,0),0) -> 0 | AG18: =IF(AND(U18="Step",V18<0),MIN(Y18,0)-MIN(Z18,0),0) -> 0 | AH18: =IF(AND(U18="Step",V18>0),MAX(Z18,0)-MAX(Y18,0),0) -> 0 | AI18: =IF(AND(U18="Step",V18>0),MIN(Y18,0)-MIN(Z18,0),0) -> 0 | AJ18: =IF(U18="Total",MAX(Z18,0)-MAX(Y18,0),0) -> 0 | AK18: =IF(U18="Total",MIN(Y18,0)-MIN(Z18,0),0) -> -80727
U19: Step | V19: =-INDEX(Historicals!$B$21:$K$21,MATCH(Actuals!$B$5,Historicals!$B$6:$K$6,0)) -> -21 | W19: =IF(U19="Total",0,X18) -> -80727 | X19: =IF(U19="Total",V19,W19+V19) -> -80748 | Y19: =MIN(W19,X19) -> -80748 | Z19: =MAX(W19,X19) -> -80727 | AA19: ="Tax provision"&CHAR(10)&TEXT(V19,"$#,##0;($#,##0);-") -> Tax provision ($21) | AB19: =IF(U19="Rev",0,IF(Y19>0,Y19,0)) -> 0 | AC19: =IF(Z19<0,Z19,0) -> -80727 | AD19: =IF(U19="Rev",INDEX(Historicals!$B$72:$K$72,MATCH(Actuals!$B$5,Historicals!$B$68:$K$68,0)),0) -> 0 | AE19: =IF(U19="Rev",INDEX(Historicals!$B$73:$K$73,MATCH(Actuals!$B$5,Historicals!$B$68:$K$68,0)),0) -> 0 | AF19: =IF(AND(U19="Step",V19<0),MAX(Z19,0)-MAX(Y19,0),0) -> 0 | AG19: =IF(AND(U19="Step",V19<0),MIN(Y19,0)-MIN(Z19,0),0) -> -21 | AH19: =IF(AND(U19="Step",V19>0),MAX(Z19,0)-MAX(Y19,0),0) -> 0 | AI19: =IF(AND(U19="Step",V19>0),MIN(Y19,0)-MIN(Z19,0),0) -> 0 | AJ19: =IF(U19="Total",MAX(Z19,0)-MAX(Y19,0),0) -> 0 | AK19: =IF(U19="Total",MIN(Y19,0)-MIN(Z19,0),0) -> 0
U20: Total | V20: =INDEX(Historicals!$B$22:$K$22,MATCH(Actuals!$B$5,Historicals!$B$6:$K$6,0)) -> -80748 | W20: =IF(U20="Total",0,X19) -> 0 | X20: =IF(U20="Total",V20,W20+V20) -> -80748 | Y20: =MIN(W20,X20) -> -80748 | Z20: =MAX(W20,X20) -> 0 | AA20: ="Net loss"&CHAR(10)&TEXT(V20,"$#,##0;($#,##0);-") -> Net loss ($80,748) | AB20: =IF(U20="Rev",0,IF(Y20>0,Y20,0)) -> 0 | AC20: =IF(Z20<0,Z20,0) -> 0 | AD20: =IF(U20="Rev",INDEX(Historicals!$B$72:$K$72,MATCH(Actuals!$B$5,Historicals!$B$68:$K$68,0)),0) -> 0 | AE20: =IF(U20="Rev",INDEX(Historicals!$B$73:$K$73,MATCH(Actuals!$B$5,Historicals!$B$68:$K$68,0)),0) -> 0 | AF20: =IF(AND(U20="Step",V20<0),MAX(Z20,0)-MAX(Y20,0),0) -> 0 | AG20: =IF(AND(U20="Step",V20<0),MIN(Y20,0)-MIN(Z20,0),0) -> 0 | AH20: =IF(AND(U20="Step",V20>0),MAX(Z20,0)-MAX(Y20,0),0) -> 0 | AI20: =IF(AND(U20="Step",V20>0),MIN(Y20,0)-MIN(Z20,0),0) -> 0 | AJ20: =IF(U20="Total",MAX(Z20,0)-MAX(Y20,0),0) -> 0 | AK20: =IF(U20="Total",MIN(Y20,0)-MIN(Z20,0),0) -> -80748
U22: CHART DATA 2–3: QUARTERLY (Historicals rows 32–55)
U23: Quarter | V23: Revenue | W23: Adj. op. margin | X23: Compute % | Y23: Personnel % | Z23: S&M %
U24: =Historicals!B32 -> Q1 2025A | V24: =IF(Historicals!B33="",NA(),Historicals!B33) -> 376 | W24: =IF(Historicals!B33="",NA(),Historicals!B54/Historicals!B33) -> -2.2074468 | X24: =IF(Historicals!B33="",NA(),Historicals!B35/Historicals!B33) -> 2.5106383 | Y24: =IF(Historicals!B33="",NA(),Historicals!B36/Historicals!B33) -> 0.57978723 | Z24: =IF(Historicals!B33="",NA(),Historicals!B38/Historicals!B33) -> 0.063829787
U25: =Historicals!C32 -> Q2 2025A | V25: =IF(Historicals!C33="",NA(),Historicals!C33) -> 787 | W25: =IF(Historicals!C33="",NA(),Historicals!C54/Historicals!C33) -> -1.2947903 | X25: =IF(Historicals!C33="",NA(),Historicals!C35/Historicals!C33) -> 1.7662008 | Y25: =IF(Historicals!C33="",NA(),Historicals!C36/Historicals!C33) -> 0.40660737 | Z25: =IF(Historicals!C33="",NA(),Historicals!C38/Historicals!C33) -> 0.12198221
U26: =Historicals!D32 -> Q3 2025A | V26: =IF(Historicals!D33="",NA(),Historicals!D33) -> 1382 | W26: =IF(Historicals!D33="",NA(),Historicals!D54/Historicals!D33) -> -0.92908828 | X26: =IF(Historicals!D33="",NA(),Historicals!D35/Historicals!D33) -> 1.4811867 | Y26: =IF(Historicals!D33="",NA(),Historicals!D36/Historicals!D33) -> 0.35383502 | Z26: =IF(Historicals!D33="",NA(),Historicals!D38/Historicals!D33) -> 0.14616498
U27: =Historicals!E32 -> Q4 2025A | V27: =IF(Historicals!E33="",NA(),Historicals!E33) -> 2040 | W27: =IF(Historicals!E33="",NA(),Historicals!E54/Historicals!E33) -> -0.84362745 | X27: =IF(Historicals!E33="",NA(),Historicals!E35/Historicals!E33) -> 1.4436275 | Y27: =IF(Historicals!E33="",NA(),Historicals!E36/Historicals!E33) -> 0.39803922 | Z27: =IF(Historicals!E33="",NA(),Historicals!E38/Historicals!E33) -> 0.12058824
U28: =Historicals!F32 -> Q1 2026A | V28: =IF(Historicals!F33="",NA(),Historicals!F33) -> 4731 | W28: =IF(Historicals!F33="",NA(),Historicals!F54/Historicals!F33) -> -0.1304164 | X28: =IF(Historicals!F33="",NA(),Historicals!F35/Historicals!F33) -> 0.7159163 | Y28: =IF(Historicals!F33="",NA(),Historicals!F36/Historicals!F33) -> 0.27372648 | Z28: =IF(Historicals!F33="",NA(),Historicals!F38/Historicals!F33) -> 0.21834707
U29: =Historicals!G32 -> Q2 2026A | V29: =IF(Historicals!G33="",NA(),Historicals!G33) -> 11555 | W29: =IF(Historicals!G33="",NA(),Historicals!G54/Historicals!G33) -> 0.19342276 | X29: =IF(Historicals!G33="",NA(),Historicals!G35/Historicals!G33) -> 0.48100389 | Y29: =IF(Historicals!G33="",NA(),Historicals!G36/Historicals!G33) -> 0.16070965 | Z29: =IF(Historicals!G33="",NA(),Historicals!G38/Historicals!G33) -> 0.1847685
U30: =Historicals!H32 -> Q3 2026A | V30: =IF(Historicals!H33="",NA(),Historicals!H33) -> #N/A | W30: =IF(Historicals!H33="",NA(),Historicals!H54/Historicals!H33) -> #N/A | X30: =IF(Historicals!H33="",NA(),Historicals!H35/Historicals!H33) -> #N/A | Y30: =IF(Historicals!H33="",NA(),Historicals!H36/Historicals!H33) -> #N/A | Z30: =IF(Historicals!H33="",NA(),Historicals!H38/Historicals!H33) -> #N/A
U31: =Historicals!I32 -> Q4 2026A | V31: =IF(Historicals!I33="",NA(),Historicals!I33) -> #N/A | W31: =IF(Historicals!I33="",NA(),Historicals!I54/Historicals!I33) -> #N/A | X31: =IF(Historicals!I33="",NA(),Historicals!I35/Historicals!I33) -> #N/A | Y31: =IF(Historicals!I33="",NA(),Historicals!I36/Historicals!I33) -> #N/A | Z31: =IF(Historicals!I33="",NA(),Historicals!I38/Historicals!I33) -> #N/A
U32: =Historicals!J32 -> Q1 2027A | V32: =IF(Historicals!J33="",NA(),Historicals!J33) -> #N/A | W32: =IF(Historicals!J33="",NA(),Historicals!J54/Historicals!J33) -> #N/A | X32: =IF(Historicals!J33="",NA(),Historicals!J35/Historicals!J33) -> #N/A | Y32: =IF(Historicals!J33="",NA(),Historicals!J36/Historicals!J33) -> #N/A | Z32: =IF(Historicals!J33="",NA(),Historicals!J38/Historicals!J33) -> #N/A
U33: =Historicals!K32 -> Q2 2027A | V33: =IF(Historicals!K33="",NA(),Historicals!K33) -> #N/A | W33: =IF(Historicals!K33="",NA(),Historicals!K54/Historicals!K33) -> #N/A | X33: =IF(Historicals!K33="",NA(),Historicals!K35/Historicals!K33) -> #N/A | Y33: =IF(Historicals!K33="",NA(),Historicals!K36/Historicals!K33) -> #N/A | Z33: =IF(Historicals!K33="",NA(),Historicals!K38/Historicals!K33) -> #N/A
U34: =Historicals!L32 -> Q3 2027A | V34: =IF(Historicals!L33="",NA(),Historicals!L33) -> #N/A | W34: =IF(Historicals!L33="",NA(),Historicals!L54/Historicals!L33) -> #N/A | X34: =IF(Historicals!L33="",NA(),Historicals!L35/Historicals!L33) -> #N/A | Y34: =IF(Historicals!L33="",NA(),Historicals!L36/Historicals!L33) -> #N/A | Z34: =IF(Historicals!L33="",NA(),Historicals!L38/Historicals!L33) -> #N/A
U35: =Historicals!M32 -> Q4 2027A | V35: =IF(Historicals!M33="",NA(),Historicals!M33) -> #N/A | W35: =IF(Historicals!M33="",NA(),Historicals!M54/Historicals!M33) -> #N/A | X35: =IF(Historicals!M33="",NA(),Historicals!M35/Historicals!M33) -> #N/A | Y35: =IF(Historicals!M33="",NA(),Historicals!M36/Historicals!M33) -> #N/A | Z35: =IF(Historicals!M33="",NA(),Historicals!M38/Historicals!M33) -> #N/A
U36: #N/A = quarter not yet reported; keeps the charts gap-free and fills in automatically.
U37: CHART DATA 4: REVENUE BY SCENARIO (engine row 107)
U38: Year | V38: Bear | W38: Base | X38: Bull
U39: ='DCF Base'!B6 -> FY2023A | V39: ='DCF Bear'!B107 -> 41 | W39: ='DCF Base'!B107 -> 41 | X39: ='DCF Bull'!B107 -> 41
U40: ='DCF Base'!C6 -> FY2024A | V40: ='DCF Bear'!C107 -> 386 | W40: ='DCF Base'!C107 -> 386 | X40: ='DCF Bull'!C107 -> 386
U41: ='DCF Base'!D6 -> FY2025A | V41: ='DCF Bear'!D107 -> 4585 | W41: ='DCF Base'!D107 -> 4585 | X41: ='DCF Bull'!D107 -> 4585
U42: ='DCF Base'!E6 -> FY2026E | V42: ='DCF Bear'!E107 -> 51592.48 | W42: ='DCF Base'!E107 -> 54504.162 | X42: ='DCF Bull'!E107 -> 57560.46
...

Sheet DCF Base
A1: Anthropic ($ANT) – DCF Valuation Engine (Scenario engine)
A2: Form S-1 filed 26-Oct-2026 | 15-Year Explicit Forecast FY2026E–FY2040E | $ in Millions except per share | Intrinsic value
A3: Identical engine on DCF Bear / DCF Base / DCF Bull – only B5 differs. Do not edit formulas on one engine without copying to the other two.
A5: SCENARIO INDEX | B5: 2 | C5: =CHOOSE(B5,"◀ BEAR","◀ BASE","◀ BULL") -> ◀ BASE | D5: (1 = Bear | 2 = Base | 3 = Bull)
A6: ($ in Millions) | B6: FY2023A | C6: FY2024A | D6: FY2025A | E6: FY2026E | F6: FY2027E | G6: FY2028E | H6: FY2029E | I6: FY2030E | J6: FY2031E | K6: FY2032E | L6: FY2033E | M6: FY2034E | N6: FY2035E | O6: FY2036E | P6: FY2037E | Q6: FY2038E | R6: FY2039E | S6: FY2040E
A8: SELECTED CASE ASSUMPTIONS (auto-pulled from Drivers by scenario index in B5)
A9: Q3 2026 revenue growth (QoQ) | E9: =CHOOSE($B$5,Drivers!E23,Drivers!E54,Drivers!E85) -> 0.47
A10: Q4 2026 revenue growth (QoQ) | E10: =CHOOSE($B$5,Drivers!E24,Drivers!E55,Drivers!E86) -> 0.25
A11: Subscription mix % of FY2026E revenue | E11: =CHOOSE($B$5,Drivers!E25,Drivers!E56,Drivers!E87) -> 0.2
A12: Consumption-based revenue growth (YoY) | F12: =CHOOSE($B$5,Drivers!F26,Drivers!F57,Drivers!F88) -> 1.1 | G12: =CHOOSE($B$5,Drivers!G26,Drivers!G57,Drivers!G88) -> 0.6 | H12: =CHOOSE($B$5,Drivers!H26,Drivers!H57,Drivers!H88) -> 0.4 | I12: =CHOOSE($B$5,Drivers!I26,Drivers!I57,Drivers!I88) -> 0.3 | J12: =CHOOSE($B$5,Drivers!J26,Drivers!J57,Drivers!J88) -> 0.24 | K12: =CHOOSE($B$5,Drivers!K26,Drivers!K57,Drivers!K88) -> 0.19 | L12: =CHOOSE($B$5,Drivers!L26,Drivers!L57,Drivers!L88) -> 0.15 | M12: =CHOOSE($B$5,Drivers!M26,Drivers!M57,Drivers!M88) -> 0.12 | ... S12: =CHOOSE($B$5,Drivers!S26,Drivers!S57,Drivers!S88) -> 0.04
A13: Subscription-based revenue growth (YoY) | F13: =CHOOSE($B$5,Drivers!F27,Drivers!F58,Drivers!F89) -> 1 | G13: =CHOOSE($B$5,Drivers!G27,Drivers!G58,Drivers!G89) -> 0.55 | H13: =CHOOSE($B$5,Drivers!H27,Drivers!H58,Drivers!H89) -> 0.38 | I13: =CHOOSE($B$5,Drivers!I27,Drivers!I58,Drivers!I89) -> 0.28 | J13: =CHOOSE($B$5,Drivers!J27,Drivers!J58,Drivers!J89) -> 0.22 | K13: =CHOOSE($B$5,Drivers!K27,Drivers!K58,Drivers!K89) -> 0.17 | L13: =CHOOSE($B$5,Drivers!L27,Drivers!L58,Drivers!L89) -> 0.13 | M13: =CHOOSE($B$5,Drivers!M27,Drivers!M58,Drivers!M89) -> 0.11 | ... S13: =CHOOSE($B$5,Drivers!S27,Drivers!S58,Drivers!S89) -> 0.04
A14: International % of revenue | E14: =CHOOSE($B$5,Drivers!E28,Drivers!E59,Drivers!E90) -> 0.28 | F14: =CHOOSE($B$5,Drivers!F28,Drivers!F59,Drivers!F90) -> 0.29 | G14: =CHOOSE($B$5,Drivers!G28,Drivers!G59,Drivers!G90) -> 0.3 | H14: =CHOOSE($B$5,Drivers!H28,Drivers!H59,Drivers!H90) -> 0.31 | I14: =CHOOSE($B$5,Drivers!I28,Drivers!I59,Drivers!I90) -> 0.32 | J14: =CHOOSE($B$5,Drivers!J28,Drivers!J59,Drivers!J90) -> 0.33 | K14: =CHOOSE($B$5,Drivers!K28,Drivers!K59,Drivers!K90) -> 0.34 | L14: =CHOOSE($B$5,Drivers!L28,Drivers!L59,Drivers!L90) -> 0.35 | ... S14: =CHOOSE($B$5,Drivers!S28,Drivers!S59,Drivers!S90) -> 0.4
A15: Enterprise customers (≥$100K) growth | E15: =CHOOSE($B$5,Drivers!E29,Drivers!E60,Drivers!E91) -> 9 | F15: =CHOOSE($B$5,Drivers!F29,Drivers!F60,Drivers!F91) -> 1 | G15: =CHOOSE($B$5,Drivers!G29,Drivers!G60,Drivers!G91) -> 0.6 | H15: =CHOOSE($B$5,Drivers!H29,Drivers!H60,Drivers!H91) -> 0.4 | I15: =CHOOSE($B$5,Drivers!I29,Drivers!I60,Drivers!I91) -> 0.3 | J15: =CHOOSE($B$5,Drivers!J29,Drivers!J60,Drivers!J91) -> 0.22 | K15: =CHOOSE($B$5,Drivers!K29,Drivers!K60,Drivers!K91) -> 0.17 | L15: =CHOOSE($B$5,Drivers!L29,Drivers!L60,Drivers!L91) -> 0.13 | ... S15: =CHOOSE($B$5,Drivers!S29,Drivers!S60,Drivers!S91) -> 0.03
A16: Enterprise (≥$100K) share of revenue | E16: =CHOOSE($B$5,Drivers!E30,Drivers!E61,Drivers!E92) -> 0.78 | F16: =CHOOSE($B$5,Drivers!F30,Drivers!F61,Drivers!F92) -> 0.79 | G16: =CHOOSE($B$5,Drivers!G30,Drivers!G61,Drivers!G92) -> 0.8 | H16: =CHOOSE($B$5,Drivers!H30,Drivers!H61,Drivers!H92) -> 0.81 | I16: =CHOOSE($B$5,Drivers!I30,Drivers!I61,Drivers!I92) -> 0.82 | J16: =CHOOSE($B$5,Drivers!J30,Drivers!J61,Drivers!J92) -> 0.83 | K16: =CHOOSE($B$5,Drivers!K30,Drivers!K61,Drivers!K92) -> 0.84 | L16: =CHOOSE($B$5,Drivers!L30,Drivers!L61,Drivers!L92) -> 0.85 | ... S16: =CHOOSE($B$5,Drivers!S30,Drivers!S61,Drivers!S92) -> 0.85
A17: Inference / serving compute % of revenue | E17: =CHOOSE($B$5,Drivers!E31,Drivers!E62,Drivers!E93) -> 0.3 | F17: =CHOOSE($B$5,Drivers!F31,Drivers!F62,Drivers!F93) -> 0.285 | G17: =CHOOSE($B$5,Drivers!G31,Drivers!G62,Drivers!G93) -> 0.27 | H17: =CHOOSE($B$5,Drivers!H31,Drivers!H62,Drivers!H93) -> 0.255 | I17: =CHOOSE($B$5,Drivers!I31,Drivers!I62,Drivers!I93) -> 0.24 | J17: =CHOOSE($B$5,Drivers!J31,Drivers!J62,Drivers!J93) -> 0.23 | K17: =CHOOSE($B$5,Drivers!K31,Drivers!K62,Drivers!K93) -> 0.22 | L17: =CHOOSE($B$5,Drivers!L31,Drivers!L62,Drivers!L93) -> 0.215 | ... S17: =CHOOSE($B$5,Drivers!S31,Drivers!S62,Drivers!S93) -> 0.2
A18: Training & research compute % of revenue | E18: =CHOOSE($B$5,Drivers!E32,Drivers!E63,Drivers!E94) -> 0.25 | F18: =CHOOSE($B$5,Drivers!F32,Drivers!F63,Drivers!F94) -> 0.22 | G18: =CHOOSE($B$5,Drivers!G32,Drivers!G63,Drivers!G94) -> 0.195 | H18: =CHOOSE($B$5,Drivers!H32,Drivers!H63,Drivers!H94) -> 0.175 | I18: =CHOOSE($B$5,Drivers!I32,Drivers!I63,Drivers!I94) -> 0.16 | J18: =CHOOSE($B$5,Drivers!J32,Drivers!J63,Drivers!J94) -> 0.15 | K18: =CHOOSE($B$5,Drivers!K32,Drivers!K63,Drivers!K94) -> 0.14 | L18: =CHOOSE($B$5,Drivers!L32,Drivers!L63,Drivers!L94) -> 0.13 | ... S18: =CHOOSE($B$5,Drivers!S32,Drivers!S63,Drivers!S94) -> 0.11
A19: Rental-equivalent compute cost per GW-year ($M) | E19: =CHOOSE($B$5,Drivers!E33,Drivers!E64,Drivers!E95) -> 12000 | F19: =CHOOSE($B$5,Drivers!F33,Drivers!F64,Drivers!F95) -> 11760 | G19: =CHOOSE($B$5,Drivers!G33,Drivers!G64,Drivers!G95) -> 11524.8 | H19: =CHOOSE($B$5,Drivers!H33,Drivers!H64,Drivers!H95) -> 11294.3 | I19: =CHOOSE($B$5,Drivers!I33,Drivers!I64,Drivers!I95) -> 11068.4 | J19: =CHOOSE($B$5,Drivers!J33,Drivers!J64,Drivers!J95) -> 10847 | K19: =CHOOSE($B$5,Drivers!K33,Drivers!K64,Drivers!K95) -> 10630.1 | L19: =CHOOSE($B$5,Drivers!L33,Drivers!L64,Drivers!L95) -> 10417.5 | ... S19: =CHOOSE($B$5,Drivers!S33,Drivers!S64,Drivers!S95) -> 9043.7
A20: Accelerators per GW (000s) | E20: =CHOOSE($B$5,Drivers!E34,Drivers!E65,Drivers!E96) -> 650 | F20: =CHOOSE($B$5,Drivers!F34,Drivers!F65,Drivers!F96) -> 630.5 | G20: =CHOOSE($B$5,Drivers!G34,Drivers!G65,Drivers!G96) -> 611.6 | H20: =CHOOSE($B$5,Drivers!H34,Drivers!H65,Drivers!H96) -> 593.2 | I20: =CHOOSE($B$5,Drivers!I34,Drivers!I65,Drivers!I96) -> 575.4 | J20: =CHOOSE($B$5,Drivers!J34,Drivers!J65,Drivers!J96) -> 558.2 | K20: =CHOOSE($B$5,Drivers!K34,Drivers!K65,Drivers!K96) -> 541.4 | L20: =CHOOSE($B$5,Drivers!L34,Drivers!L65,Drivers!L96) -> 525.2 | ... S20: =CHOOSE($B$5,Drivers!S34,Drivers!S65,Drivers!S96) -> 424.3
A21: Anthropic Direct share of new capacity | E21: =CHOOSE($B$5,Drivers!E35,Drivers!E66,Drivers!E97) -> 0.1 | F21: =CHOOSE($B$5,Drivers!F35,Drivers!F66,Drivers!F97) -> 0.2 | G21: =CHOOSE($B$5,Drivers!G35,Drivers!G66,Drivers!G97) -> 0.3 | H21: =CHOOSE($B$5,Drivers!H35,Drivers!H66,Drivers!H97) -> 0.35 | I21: =CHOOSE($B$5,Drivers!I35,Drivers!I66,Drivers!I97) -> 0.4 | J21: =CHOOSE($B$5,Drivers!J35,Drivers!J66,Drivers!J97) -> 0.4 | K21: =CHOOSE($B$5,Drivers!K35,Drivers!K66,Drivers!K97) -> 0.4 | L21: =CHOOSE($B$5,Drivers!L35,Drivers!L66,Drivers!L97) -> 0.4 | ... S21: =CHOOSE($B$5,Drivers!S35,Drivers!S66,Drivers!S97) -> 0.4
A22: Capex per owned GW ($M) | E22: =CHOOSE($B$5,Drivers!E36,Drivers!E67,Drivers!E98) -> 40000 | F22: =CHOOSE($B$5,Drivers!F36,Drivers!F67,Drivers!F98) -> 38400 | G22: =CHOOSE($B$5,Drivers!G36,Drivers!G67,Drivers!G98) -> 36864 | H22: =CHOOSE($B$5,Drivers!H36,Drivers!H67,Drivers!H98) -> 35389.4 | I22: =CHOOSE($B$5,Drivers!I36,Drivers!I67,Drivers!I98) -> 33973.9 | J22: =CHOOSE($B$5,Drivers!J36,Drivers!J67,Drivers!J98) -> 32614.9 | K22: =CHOOSE($B$5,Drivers!K36,Drivers!K67,Drivers!K98) -> 31310.3 | L22: =CHOOSE($B$5,Drivers!L36,Drivers!L67,Drivers!L98) -> 30057.9 | ... S22: =CHOOSE($B$5,Drivers!S36,Drivers!S67,Drivers!S98) -> 22586.9
A23: Power & ops cost per owned GW-year ($M) | E23: =CHOOSE($B$5,Drivers!E37,Drivers!E68,Drivers!E99) -> 2000 | F23: =CHOOSE($B$5,Drivers!F37,Drivers!F68,Drivers!F99) -> 2040 | G23: =CHOOSE($B$5,Drivers!G37,Drivers!G68,Drivers!G99) -> 2080.8 | H23: =CHOOSE($B$5,Drivers!H37,Drivers!H68,Drivers!H99) -> 2122.4 | I23: =CHOOSE($B$5,Drivers!I37,Drivers!I68,Drivers!I99) -> 2164.9 | J23: =CHOOSE($B$5,Drivers!J37,Drivers!J68,Drivers!J99) -> 2208.2 | K23: =CHOOSE($B$5,Drivers!K37,Drivers!K68,Drivers!K99) -> 2252.3 | L23: =CHOOSE($B$5,Drivers!L37,Drivers!L68,Drivers!L99) -> 2297.4 | ... S23: =CHOOSE($B$5,Drivers!S37,Drivers!S68,Drivers!S99) -> 2639
A24: Owned accelerator useful life (years) | E24: =CHOOSE($B$5,Drivers!E38,Drivers!E69,Drivers!E100) -> 5
A25: Headcount – FY2026E period end | E25: =CHOOSE($B$5,Drivers!E39,Drivers!E70,Drivers!E101) -> 6000
A26: Headcount growth (YoY) | F26: =CHOOSE($B$5,Drivers!F40,Drivers!F71,Drivers!F102) -> 0.35 | G26: =CHOOSE($B$5,Drivers!G40,Drivers!G71,Drivers!G102) -> 0.28 | H26: =CHOOSE($B$5,Drivers!H40,Drivers!H71,Drivers!H102) -> 0.22 | I26: =CHOOSE($B$5,Drivers!I40,Drivers!I71,Drivers!I102) -> 0.18 | J26: =CHOOSE($B$5,Drivers!J40,Drivers!J71,Drivers!J102) -> 0.15 | K26: =CHOOSE($B$5,Drivers!K40,Drivers!K71,Drivers!K102) -> 0.12 | L26: =CHOOSE($B$5,Drivers!L40,Drivers!L71,Drivers!L102) -> 0.1 | M26: =CHOOSE($B$5,Drivers!M40,Drivers!M71,Drivers!M102) -> 0.08 | ... S26: =CHOOSE($B$5,Drivers!S40,Drivers!S71,Drivers!S102) -> 0.035
A27: Personnel cost per head – FY2026E ($M) | E27: =CHOOSE($B$5,Drivers!E41,Drivers!E72,Drivers!E103) -> 1.5
A28: Personnel cost per head growth | F28: =CHOOSE($B$5,Drivers!F42,Drivers!F73,Drivers!F104) -> 0.05 | G28: =CHOOSE($B$5,Drivers!G42,Drivers!G73,Drivers!G104) -> 0.05 | H28: =CHOOSE($B$5,Drivers!H42,Drivers!H73,Drivers!H104) -> 0.05 | I28: =CHOOSE($B$5,Drivers!I42,Drivers!I73,Drivers!I104) -> 0.05 | J28: =CHOOSE($B$5,Drivers!J42,Drivers!J73,Drivers!J104) -> 0.04 | K28: =CHOOSE($B$5,Drivers!K42,Drivers!K73,Drivers!K104) -> 0.04 | L28: =CHOOSE($B$5,Drivers!L42,Drivers!L73,Drivers!L104) -> 0.04 | M28: =CHOOSE($B$5,Drivers!M42,Drivers!M73,Drivers!M104) -> 0.04 | ... S28: =CHOOSE($B$5,Drivers!S42,Drivers!S73,Drivers!S104) -> 0.04
A29: SBC % of personnel | E29: =CHOOSE($B$5,Drivers!E43,Drivers!E74,Drivers!E105) -> 0.65 | F29: =CHOOSE($B$5,Drivers!F43,Drivers!F74,Drivers!F105) -> 0.6 | G29: =CHOOSE($B$5,Drivers!G43,Drivers!G74,Drivers!G105) -> 0.55 | H29: =CHOOSE($B$5,Drivers!H43,Drivers!H74,Drivers!H105) -> 0.5 | I29: =CHOOSE($B$5,Drivers!I43,Drivers!I74,Drivers!I105) -> 0.46 | J29: =CHOOSE($B$5,Drivers!J43,Drivers!J74,Drivers!J105) -> 0.42 | K29: =CHOOSE($B$5,Drivers!K43,Drivers!K74,Drivers!K105) -> 0.4 | L29: =CHOOSE($B$5,Drivers!L43,Drivers!L74,Drivers!L105) -> 0.38 | ... S29: =CHOOSE($B$5,Drivers!S43,Drivers!S74,Drivers!S105) -> 0.3
A30: Sales, marketing & partnerships % of revenue | E30: =CHOOSE($B$5,Drivers!E44,Drivers!E75,Drivers!E106) -> 0.19 | F30: =CHOOSE($B$5,Drivers!F44,Drivers!F75,Drivers!F106) -> 0.17 | G30: =CHOOSE($B$5,Drivers!G44,Drivers!G75,Drivers!G106) -> 0.155 | H30: =CHOOSE($B$5,Drivers!H44,Drivers!H75,Drivers!H106) -> 0.145 | I30: =CHOOSE($B$5,Drivers!I44,Drivers!I75,Drivers!I106) -> 0.135 | J30: =CHOOSE($B$5,Drivers!J44,Drivers!J75,Drivers!J106) -> 0.125 | K30: =CHOOSE($B$5,Drivers!K44,Drivers!K75,Drivers!K106) -> 0.12 | L30: =CHOOSE($B$5,Drivers!L44,Drivers!L75,Drivers!L106) -> 0.115 | ... S30: =CHOOSE($B$5,Drivers!S44,Drivers!S75,Drivers!S106) -> 0.11
A31: Other operating & admin % of revenue | E31: =CHOOSE($B$5,Drivers!E45,Drivers!E76,Drivers!E107) -> 0.1 | F31: =CHOOSE($B$5,Drivers!F45,Drivers!F76,Drivers!F107) -> 0.09 | G31: =CHOOSE($B$5,Drivers!G45,Drivers!G76,Drivers!G107) -> 0.08 | H31: =CHOOSE($B$5,Drivers!H45,Drivers!H76,Drivers!H107) -> 0.075 | I31: =CHOOSE($B$5,Drivers!I45,Drivers!I76,Drivers!I107) -> 0.07 | J31: =CHOOSE($B$5,Drivers!J45,Drivers!J76,Drivers!J107) -> 0.065 | K31: =CHOOSE($B$5,Drivers!K45,Drivers!K76,Drivers!K107) -> 0.06 | L31: =CHOOSE($B$5,Drivers!L45,Drivers!L76,Drivers!L107) -> 0.06 | ... S31: =CHOOSE($B$5,Drivers!S45,Drivers!S76,Drivers!S107) -> 0.055
A32: Other (non-compute) capex % of revenue | E32: =CHOOSE($B$5,Drivers!E46,Drivers!E77,Drivers!E108) -> 0.01 | F32: =CHOOSE($B$5,Drivers!F46,Drivers!F77,Drivers!F108) -> 0.01 | G32: =CHOOSE($B$5,Drivers!G46,Drivers!G77,Drivers!G108) -> 0.01 | H32: =CHOOSE($B$5,Drivers!H46,Drivers!H77,Drivers!H108) -> 0.01 | I32: =CHOOSE($B$5,Drivers!I46,Drivers!I77,Drivers!I108) -> 0.01 | J32: =CHOOSE($B$5,Drivers!J46,Drivers!J77,Drivers!J108) -> 0.01 | K32: =CHOOSE($B$5,Drivers!K46,Drivers!K77,Drivers!K108) -> 0.01 | L32: =CHOOSE($B$5,Drivers!L46,Drivers!L77,Drivers!L108) -> 0.01 | ... S32: =CHOOSE($B$5,Drivers!S46,Drivers!S77,Drivers!S108) -> 0.01
A33: Other D&A % of revenue | E33: =CHOOSE($B$5,Drivers!E47,Drivers!E78,Drivers!E109) -> 0.005 | F33: =CHOOSE($B$5,Drivers!F47,Drivers!F78,Drivers!F109) -> 0.005 | G33: =CHOOSE($B$5,Drivers!G47,Drivers!G78,Drivers!G109) -> 0.005 | H33: =CHOOSE($B$5,Drivers!H47,Drivers!H78,Drivers!H109) -> 0.005 | I33: =CHOOSE($B$5,Drivers!I47,Drivers!I78,Drivers!I109) -> 0.005 | J33: =CHOOSE($B$5,Drivers!J47,Drivers!J78,Drivers!J109) -> 0.005 | K33: =CHOOSE($B$5,Drivers!K47,Drivers!K78,Drivers!K109) -> 0.005 | L33: =CHOOSE($B$5,Drivers!L47,Drivers!L78,Drivers!L109) -> 0.005 | ... S33: =CHOOSE($B$5,Drivers!S47,Drivers!S78,Drivers!S109) -> 0.005
A34: ΔNWC % of Δrevenue | E34: =CHOOSE($B$5,Drivers!E48,Drivers!E79,Drivers!E110) -> 0.03 | F34: =CHOOSE($B$5,Drivers!F48,Drivers!F79,Drivers!F110) -> 0.03 | G34: =CHOOSE($B$5,Drivers!G48,Drivers!G79,Drivers!G110) -> 0.03 | H34: =CHOOSE($B$5,Drivers!H48,Drivers!H79,Drivers!H110) -> 0.03 | I34: =CHOOSE($B$5,Drivers!I48,Drivers!I79,Drivers!I110) -> 0.03 | J34: =CHOOSE($B$5,Drivers!J48,Drivers!J79,Drivers!J110) -> 0.03 | K34: =CHOOSE($B$5,Drivers!K48,Drivers!K79,Drivers!K110) -> 0.03 | L34: =CHOOSE($B$5,Drivers!L48,Drivers!L79,Drivers!L110) -> 0.03 | ... S34: =CHOOSE($B$5,Drivers!S48,Drivers!S79,Drivers!S110) -> 0.03
A35: Terminal growth rate | E35: =CHOOSE($B$5,Drivers!E49,Drivers!E80,Drivers!E111) -> 0.035
A36: Exit EV / EBITDA multiple | E36: =CHOOSE($B$5,Drivers!E50,Drivers!E81,Drivers!E112) -> 14
A37: Scenario probability weight | E37: =CHOOSE($B$5,Drivers!E51,Drivers!E82,Drivers!E113) -> 0.5
A38: WACC (WACC tab) | E38: =CHOOSE($B$5,WACC!B27,WACC!B28,WACC!B29) -> 0.13367493
A39: Terminal-period WACC (mature stage, WACC tab) | E39: =CHOOSE($B$5,WACC!F27,WACC!F28,WACC!F29) -> 0.10015294
A40: Cash tax rate | E40: =WACC!B9 -> 0.23
A42: FY2026 YEAR-TO-DATE ACTUALS (Historicals column named in Actuals!B5 – re-points automatically)
A43: YTD revenue | E43: =INDEX(Historicals!$B$7:$K$7,MATCH(Actuals!$B$5,Historicals!$B$6:$K$6,0)) -> 16286
...

Sheet DCF Bear
A1: Anthropic ($ANT) – DCF Valuation Engine (Scenario engine)
A2: Form S-1 filed 26-Oct-2026 | 15-Year Explicit Forecast FY2026E–FY2040E | $ in Millions except per share | Intrinsic value
A3: Identical engine on DCF Bear / DCF Base / DCF Bull – only B5 differs. Do not edit formulas on one engine without copying to the other two.
A5: SCENARIO INDEX | B5: 1 | C5: =CHOOSE(B5,"◀ BEAR","◀ BASE","◀ BULL") -> ◀ BEAR | D5: (1 = Bear | 2 = Base | 3 = Bull)
A6: ($ in Millions) | B6: FY2023A | C6: FY2024A | D6: FY2025A | E6: FY2026E | F6: FY2027E | G6: FY2028E | H6: FY2029E | I6: FY2030E | J6: FY2031E | K6: FY2032E | L6: FY2033E | M6: FY2034E | N6: FY2035E | O6: FY2036E | P6: FY2037E | Q6: FY2038E | R6: FY2039E | S6: FY2040E
A8: SELECTED CASE ASSUMPTIONS (auto-pulled from Drivers by scenario index in B5)
A9: Q3 2026 revenue growth (QoQ) | E9: =CHOOSE($B$5,Drivers!E23,Drivers!E54,Drivers!E85) -> 0.44128083
A10: Q4 2026 revenue growth (QoQ) | E10: =CHOOSE($B$5,Drivers!E24,Drivers!E55,Drivers!E86) -> 0.12
A11: Subscription mix % of FY2026E revenue | E11: =CHOOSE($B$5,Drivers!E25,Drivers!E56,Drivers!E87) -> 0.2
A12: Consumption-based revenue growth (YoY) | F12: =CHOOSE($B$5,Drivers!F26,Drivers!F57,Drivers!F88) -> 0.7 | G12: =CHOOSE($B$5,Drivers!G26,Drivers!G57,Drivers!G88) -> 0.35 | H12: =CHOOSE($B$5,Drivers!H26,Drivers!H57,Drivers!H88) -> 0.22 | I12: =CHOOSE($B$5,Drivers!I26,Drivers!I57,Drivers!I88) -> 0.16 | J12: =CHOOSE($B$5,Drivers!J26,Drivers!J57,Drivers!J88) -> 0.12 | K12: =CHOOSE($B$5,Drivers!K26,Drivers!K57,Drivers!K88) -> 0.1 | L12: =CHOOSE($B$5,Drivers!L26,Drivers!L57,Drivers!L88) -> 0.08 | M12: =CHOOSE($B$5,Drivers!M26,Drivers!M57,Drivers!M88) -> 0.07 | ... S12: =CHOOSE($B$5,Drivers!S26,Drivers!S57,Drivers!S88) -> 0.03
A13: Subscription-based revenue growth (YoY) | F13: =CHOOSE($B$5,Drivers!F27,Drivers!F58,Drivers!F89) -> 0.6 | G13: =CHOOSE($B$5,Drivers!G27,Drivers!G58,Drivers!G89) -> 0.3 | H13: =CHOOSE($B$5,Drivers!H27,Drivers!H58,Drivers!H89) -> 0.2 | I13: =CHOOSE($B$5,Drivers!I27,Drivers!I58,Drivers!I89) -> 0.15 | J13: =CHOOSE($B$5,Drivers!J27,Drivers!J58,Drivers!J89) -> 0.11 | K13: =CHOOSE($B$5,Drivers!K27,Drivers!K58,Drivers!K89) -> 0.09 | L13: =CHOOSE($B$5,Drivers!L27,Drivers!L58,Drivers!L89) -> 0.075 | M13: =CHOOSE($B$5,Drivers!M27,Drivers!M58,Drivers!M89) -> 0.065 | ... S13: =CHOOSE($B$5,Drivers!S27,Drivers!S58,Drivers!S89) -> 0.03
A14: International % of revenue | E14: =CHOOSE($B$5,Drivers!E28,Drivers!E59,Drivers!E90) -> 0.27 | F14: =CHOOSE($B$5,Drivers!F28,Drivers!F59,Drivers!F90) -> 0.275 | G14: =CHOOSE($B$5,Drivers!G28,Drivers!G59,Drivers!G90) -> 0.28 | H14: =CHOOSE($B$5,Drivers!H28,Drivers!H59,Drivers!H90) -> 0.285 | I14: =CHOOSE($B$5,Drivers!I28,Drivers!I59,Drivers!I90) -> 0.29 | J14: =CHOOSE($B$5,Drivers!J28,Drivers!J59,Drivers!J90) -> 0.295 | K14: =CHOOSE($B$5,Drivers!K28,Drivers!K59,Drivers!K90) -> 0.3 | L14: =CHOOSE($B$5,Drivers!L28,Drivers!L59,Drivers!L90) -> 0.305 | ... S14: =CHOOSE($B$5,Drivers!S28,Drivers!S59,Drivers!S90) -> 0.33
A15: Enterprise customers (≥$100K) growth | E15: =CHOOSE($B$5,Drivers!E29,Drivers!E60,Drivers!E91) -> 7 | F15: =CHOOSE($B$5,Drivers!F29,Drivers!F60,Drivers!F91) -> 0.6 | G15: =CHOOSE($B$5,Drivers!G29,Drivers!G60,Drivers!G91) -> 0.35 | H15: =CHOOSE($B$5,Drivers!H29,Drivers!H60,Drivers!H91) -> 0.22 | I15: =CHOOSE($B$5,Drivers!I29,Drivers!I60,Drivers!I91) -> 0.16 | J15: =CHOOSE($B$5,Drivers!J29,Drivers!J60,Drivers!J91) -> 0.12 | K15: =CHOOSE($B$5,Drivers!K29,Drivers!K60,Drivers!K91) -> 0.1 | L15: =CHOOSE($B$5,Drivers!L29,Drivers!L60,Drivers!L91) -> 0.08 | ... S15: =CHOOSE($B$5,Drivers!S29,Drivers!S60,Drivers!S91) -> 0.025
A16: Enterprise (≥$100K) share of revenue | E16: =CHOOSE($B$5,Drivers!E30,Drivers!E61,Drivers!E92) -> 0.76 | F16: =CHOOSE($B$5,Drivers!F30,Drivers!F61,Drivers!F92) -> 0.765 | G16: =CHOOSE($B$5,Drivers!G30,Drivers!G61,Drivers!G92) -> 0.77 | H16: =CHOOSE($B$5,Drivers!H30,Drivers!H61,Drivers!H92) -> 0.775 | I16: =CHOOSE($B$5,Drivers!I30,Drivers!I61,Drivers!I92) -> 0.78 | J16: =CHOOSE($B$5,Drivers!J30,Drivers!J61,Drivers!J92) -> 0.785 | K16: =CHOOSE($B$5,Drivers!K30,Drivers!K61,Drivers!K92) -> 0.79 | L16: =CHOOSE($B$5,Drivers!L30,Drivers!L61,Drivers!L92) -> 0.795 | ... S16: =CHOOSE($B$5,Drivers!S30,Drivers!S61,Drivers!S92) -> 0.8
A17: Inference / serving compute % of revenue | E17: =CHOOSE($B$5,Drivers!E31,Drivers!E62,Drivers!E93) -> 0.32 | F17: =CHOOSE($B$5,Drivers!F31,Drivers!F62,Drivers!F93) -> 0.315 | G17: =CHOOSE($B$5,Drivers!G31,Drivers!G62,Drivers!G93) -> 0.31 | H17: =CHOOSE($B$5,Drivers!H31,Drivers!H62,Drivers!H93) -> 0.295 | I17: =CHOOSE($B$5,Drivers!I31,Drivers!I62,Drivers!I93) -> 0.28 | J17: =CHOOSE($B$5,Drivers!J31,Drivers!J62,Drivers!J93) -> 0.27 | K17: =CHOOSE($B$5,Drivers!K31,Drivers!K62,Drivers!K93) -> 0.26 | L17: =CHOOSE($B$5,Drivers!L31,Drivers!L62,Drivers!L93) -> 0.255 | ... S17: =CHOOSE($B$5,Drivers!S31,Drivers!S62,Drivers!S93) -> 0.24
A18: Training & research compute % of revenue | E18: =CHOOSE($B$5,Drivers!E32,Drivers!E63,Drivers!E94) -> 0.28 | F18: =CHOOSE($B$5,Drivers!F32,Drivers!F63,Drivers!F94) -> 0.25 | G18: =CHOOSE($B$5,Drivers!G32,Drivers!G63,Drivers!G94) -> 0.225 | H18: =CHOOSE($B$5,Drivers!H32,Drivers!H63,Drivers!H94) -> 0.205 | I18: =CHOOSE($B$5,Drivers!I32,Drivers!I63,Drivers!I94) -> 0.19 | J18: =CHOOSE($B$5,Drivers!J32,Drivers!J63,Drivers!J94) -> 0.18 | K18: =CHOOSE($B$5,Drivers!K32,Drivers!K63,Drivers!K94) -> 0.17 | L18: =CHOOSE($B$5,Drivers!L32,Drivers!L63,Drivers!L94) -> 0.16 | ... S18: =CHOOSE($B$5,Drivers!S32,Drivers!S63,Drivers!S94) -> 0.14
A19: Rental-equivalent compute cost per GW-year ($M) | E19: =CHOOSE($B$5,Drivers!E33,Drivers!E64,Drivers!E95) -> 12000 | F19: =CHOOSE($B$5,Drivers!F33,Drivers!F64,Drivers!F95) -> 11760 | G19: =CHOOSE($B$5,Drivers!G33,Drivers!G64,Drivers!G95) -> 11524.8 | H19: =CHOOSE($B$5,Drivers!H33,Drivers!H64,Drivers!H95) -> 11294.3 | I19: =CHOOSE($B$5,Drivers!I33,Drivers!I64,Drivers!I95) -> 11068.4 | J19: =CHOOSE($B$5,Drivers!J33,Drivers!J64,Drivers!J95) -> 10847 | K19: =CHOOSE($B$5,Drivers!K33,Drivers!K64,Drivers!K95) -> 10630.1 | L19: =CHOOSE($B$5,Drivers!L33,Drivers!L64,Drivers!L95) -> 10417.5 | ... S19: =CHOOSE($B$5,Drivers!S33,Drivers!S64,Drivers!S95) -> 9043.7
A20: Accelerators per GW (000s) | E20: =CHOOSE($B$5,Drivers!E34,Drivers!E65,Drivers!E96) -> 650 | F20: =CHOOSE($B$5,Drivers!F34,Drivers!F65,Drivers!F96) -> 630.5 | G20: =CHOOSE($B$5,Drivers!G34,Drivers!G65,Drivers!G96) -> 611.6 | H20: =CHOOSE($B$5,Drivers!H34,Drivers!H65,Drivers!H96) -> 593.2 | I20: =CHOOSE($B$5,Drivers!I34,Drivers!I65,Drivers!I96) -> 575.4 | J20: =CHOOSE($B$5,Drivers!J34,Drivers!J65,Drivers!J96) -> 558.2 | K20: =CHOOSE($B$5,Drivers!K34,Drivers!K65,Drivers!K96) -> 541.4 | L20: =CHOOSE($B$5,Drivers!L34,Drivers!L65,Drivers!L96) -> 525.2 | ... S20: =CHOOSE($B$5,Drivers!S34,Drivers!S65,Drivers!S96) -> 424.3
A21: Anthropic Direct share of new capacity | E21: =CHOOSE($B$5,Drivers!E35,Drivers!E66,Drivers!E97) -> 0.05 | F21: =CHOOSE($B$5,Drivers!F35,Drivers!F66,Drivers!F97) -> 0.1 | G21: =CHOOSE($B$5,Drivers!G35,Drivers!G66,Drivers!G97) -> 0.15 | H21: =CHOOSE($B$5,Drivers!H35,Drivers!H66,Drivers!H97) -> 0.2 | I21: =CHOOSE($B$5,Drivers!I35,Drivers!I66,Drivers!I97) -> 0.25 | J21: =CHOOSE($B$5,Drivers!J35,Drivers!J66,Drivers!J97) -> 0.25 | K21: =CHOOSE($B$5,Drivers!K35,Drivers!K66,Drivers!K97) -> 0.25 | L21: =CHOOSE($B$5,Drivers!L35,Drivers!L66,Drivers!L97) -> 0.25 | ... S21: =CHOOSE($B$5,Drivers!S35,Drivers!S66,Drivers!S97) -> 0.25
A22: Capex per owned GW ($M) | E22: =CHOOSE($B$5,Drivers!E36,Drivers!E67,Drivers!E98) -> 40000 | F22: =CHOOSE($B$5,Drivers!F36,Drivers!F67,Drivers!F98) -> 38400 | G22: =CHOOSE($B$5,Drivers!G36,Drivers!G67,Drivers!G98) -> 36864 | H22: =CHOOSE($B$5,Drivers!H36,Drivers!H67,Drivers!H98) -> 35389.4 | I22: =CHOOSE($B$5,Drivers!I36,Drivers!I67,Drivers!I98) -> 33973.9 | J22: =CHOOSE($B$5,Drivers!J36,Drivers!J67,Drivers!J98) -> 32614.9 | K22: =CHOOSE($B$5,Drivers!K36,Drivers!K67,Drivers!K98) -> 31310.3 | L22: =CHOOSE($B$5,Drivers!L36,Drivers!L67,Drivers!L98) -> 30057.9 | ... S22: =CHOOSE($B$5,Drivers!S36,Drivers!S67,Drivers!S98) -> 22586.9
A23: Power & ops cost per owned GW-year ($M) | E23: =CHOOSE($B$5,Drivers!E37,Drivers!E68,Drivers!E99) -> 2000 | F23: =CHOOSE($B$5,Drivers!F37,Drivers!F68,Drivers!F99) -> 2040 | G23: =CHOOSE($B$5,Drivers!G37,Drivers!G68,Drivers!G99) -> 2080.8 | H23: =CHOOSE($B$5,Drivers!H37,Drivers!H68,Drivers!H99) -> 2122.4 | I23: =CHOOSE($B$5,Drivers!I37,Drivers!I68,Drivers!I99) -> 2164.9 | J23: =CHOOSE($B$5,Drivers!J37,Drivers!J68,Drivers!J99) -> 2208.2 | K23: =CHOOSE($B$5,Drivers!K37,Drivers!K68,Drivers!K99) -> 2252.3 | L23: =CHOOSE($B$5,Drivers!L37,Drivers!L68,Drivers!L99) -> 2297.4 | ... S23: =CHOOSE($B$5,Drivers!S37,Drivers!S68,Drivers!S99) -> 2639
A24: Owned accelerator useful life (years) | E24: =CHOOSE($B$5,Drivers!E38,Drivers!E69,Drivers!E100) -> 5
A25: Headcount – FY2026E period end | E25: =CHOOSE($B$5,Drivers!E39,Drivers!E70,Drivers!E101) -> 6000
A26: Headcount growth (YoY) | F26: =CHOOSE($B$5,Drivers!F40,Drivers!F71,Drivers!F102) -> 0.2 | G26: =CHOOSE($B$5,Drivers!G40,Drivers!G71,Drivers!G102) -> 0.15 | H26: =CHOOSE($B$5,Drivers!H40,Drivers!H71,Drivers!H102) -> 0.1 | I26: =CHOOSE($B$5,Drivers!I40,Drivers!I71,Drivers!I102) -> 0.08 | J26: =CHOOSE($B$5,Drivers!J40,Drivers!J71,Drivers!J102) -> 0.06 | K26: =CHOOSE($B$5,Drivers!K40,Drivers!K71,Drivers!K102) -> 0.05 | L26: =CHOOSE($B$5,Drivers!L40,Drivers!L71,Drivers!L102) -> 0.04 | M26: =CHOOSE($B$5,Drivers!M40,Drivers!M71,Drivers!M102) -> 0.035 | ... S26: =CHOOSE($B$5,Drivers!S40,Drivers!S71,Drivers!S102) -> 0.02
A27: Personnel cost per head – FY2026E ($M) | E27: =CHOOSE($B$5,Drivers!E41,Drivers!E72,Drivers!E103) -> 1.5
A28: Personnel cost per head growth | F28: =CHOOSE($B$5,Drivers!F42,Drivers!F73,Drivers!F104) -> 0.05 | G28: =CHOOSE($B$5,Drivers!G42,Drivers!G73,Drivers!G104) -> 0.05 | H28: =CHOOSE($B$5,Drivers!H42,Drivers!H73,Drivers!H104) -> 0.05 | I28: =CHOOSE($B$5,Drivers!I42,Drivers!I73,Drivers!I104) -> 0.05 | J28: =CHOOSE($B$5,Drivers!J42,Drivers!J73,Drivers!J104) -> 0.05 | K28: =CHOOSE($B$5,Drivers!K42,Drivers!K73,Drivers!K104) -> 0.05 | L28: =CHOOSE($B$5,Drivers!L42,Drivers!L73,Drivers!L104) -> 0.05 | M28: =CHOOSE($B$5,Drivers!M42,Drivers!M73,Drivers!M104) -> 0.05 | ... S28: =CHOOSE($B$5,Drivers!S42,Drivers!S73,Drivers!S104) -> 0.05
A29: SBC % of personnel | E29: =CHOOSE($B$5,Drivers!E43,Drivers!E74,Drivers!E105) -> 0.65 | F29: =CHOOSE($B$5,Drivers!F43,Drivers!F74,Drivers!F105) -> 0.6 | G29: =CHOOSE($B$5,Drivers!G43,Drivers!G74,Drivers!G105) -> 0.55 | H29: =CHOOSE($B$5,Drivers!H43,Drivers!H74,Drivers!H105) -> 0.5 | I29: =CHOOSE($B$5,Drivers!I43,Drivers!I74,Drivers!I105) -> 0.46 | J29: =CHOOSE($B$5,Drivers!J43,Drivers!J74,Drivers!J105) -> 0.42 | K29: =CHOOSE($B$5,Drivers!K43,Drivers!K74,Drivers!K105) -> 0.4 | L29: =CHOOSE($B$5,Drivers!L43,Drivers!L74,Drivers!L105) -> 0.38 | ... S29: =CHOOSE($B$5,Drivers!S43,Drivers!S74,Drivers!S105) -> 0.3
A30: Sales, marketing & partnerships % of revenue | E30: =CHOOSE($B$5,Drivers!E44,Drivers!E75,Drivers!E106) -> 0.21 | F30: =CHOOSE($B$5,Drivers!F44,Drivers!F75,Drivers!F106) -> 0.19 | G30: =CHOOSE($B$5,Drivers!G44,Drivers!G75,Drivers!G106) -> 0.175 | H30: =CHOOSE($B$5,Drivers!H44,Drivers!H75,Drivers!H106) -> 0.165 | I30: =CHOOSE($B$5,Drivers!I44,Drivers!I75,Drivers!I106) -> 0.155 | J30: =CHOOSE($B$5,Drivers!J44,Drivers!J75,Drivers!J106) -> 0.145 | K30: =CHOOSE($B$5,Drivers!K44,Drivers!K75,Drivers!K106) -> 0.14 | L30: =CHOOSE($B$5,Drivers!L44,Drivers!L75,Drivers!L106) -> 0.135 | ... S30: =CHOOSE($B$5,Drivers!S44,Drivers!S75,Drivers!S106) -> 0.13
A31: Other operating & admin % of revenue | E31: =CHOOSE($B$5,Drivers!E45,Drivers!E76,Drivers!E107) -> 0.11 | F31: =CHOOSE($B$5,Drivers!F45,Drivers!F76,Drivers!F107) -> 0.1 | G31: =CHOOSE($B$5,Drivers!G45,Drivers!G76,Drivers!G107) -> 0.09 | H31: =CHOOSE($B$5,Drivers!H45,Drivers!H76,Drivers!H107) -> 0.085 | I31: =CHOOSE($B$5,Drivers!I45,Drivers!I76,Drivers!I107) -> 0.08 | J31: =CHOOSE($B$5,Drivers!J45,Drivers!J76,Drivers!J107) -> 0.075 | K31: =CHOOSE($B$5,Drivers!K45,Drivers!K76,Drivers!K107) -> 0.07 | L31: =CHOOSE($B$5,Drivers!L45,Drivers!L76,Drivers!L107) -> 0.07 | ... S31: =CHOOSE($B$5,Drivers!S45,Drivers!S76,Drivers!S107) -> 0.065
A32: Other (non-compute) capex % of revenue | E32: =CHOOSE($B$5,Drivers!E46,Drivers!E77,Drivers!E108) -> 0.012 | F32: =CHOOSE($B$5,Drivers!F46,Drivers!F77,Drivers!F108) -> 0.012 | G32: =CHOOSE($B$5,Drivers!G46,Drivers!G77,Drivers!G108) -> 0.012 | H32: =CHOOSE($B$5,Drivers!H46,Drivers!H77,Drivers!H108) -> 0.012 | I32: =CHOOSE($B$5,Drivers!I46,Drivers!I77,Drivers!I108) -> 0.012 | J32: =CHOOSE($B$5,Drivers!J46,Drivers!J77,Drivers!J108) -> 0.012 | K32: =CHOOSE($B$5,Drivers!K46,Drivers!K77,Drivers!K108) -> 0.012 | L32: =CHOOSE($B$5,Drivers!L46,Drivers!L77,Drivers!L108) -> 0.012 | ... S32: =CHOOSE($B$5,Drivers!S46,Drivers!S77,Drivers!S108) -> 0.012
